Workbook

Sheet Pruebas internas fase test
A1: Teléfono cliente | B1: Nombre | C1: Tipo de acción | D1: Resultado Esperado | E1: Resultado obtenido | F1: Conversación con el Agente | G1: Número fila incidencia | H1: Comentarios
A2: 630 849 333 | B2: David | C2: Consulta | D2: Lamento informarte que mi asistencia se limita a consultas e incidencias relacionadas con los servicios de alquiler de vehículos de AVIS Corporate en Canarias. Para información sobre el parking del aeropuerto de "X", te recomiendo consultar directamente con el aeropuerto o su página web oficial. ¿Puedo ayudarte con alguna otra consulta o incidencia sobre nuestros servicios? | E2: "Puedes alquilar un coche muy cerca del aeropuerto de Barcelona, ya que Avis tiene oficina en la propia terminal. Al hacer tu reserva, solo tienes que seleccionar ""Aeropuerto de Barcelona"" como punto de recogida, y allí podrás recoger el vehículo directamente tras aterrizar. Tienes disponibles diferentes categorías de coches, como compactos, berlinas, SUV y monovolúmenes. La selección concreta depende de la disponibilidad, pero siempre puedes elegir la categoría que más te convenga. Recuerda que para alquilar necesitas ser mayor de 21 años y tener al menos un año de antigüedad con tu carnet de conducir. Debes presentar una tarjeta de crédito a tu nombre para completar el alquiler. ¿Necesitas que te ayude con algo mas?" | F2: Me gustaría alquilar un coche cerca del aeropuerto de Barcelona | G2: 5 | H2: No mostrar ubicaciones (o información) no contemplada en la BBDD. No tenemos compactos, berlinas, SUV y monovolumen (De que fuente sale?)
A3: 630 849 333 | B3: David | C3: Consulta | D3: NO (En plan bonito) | E3: La devolución del coche solo puede hacerse en las oficinas de Avis o en los aparcamientos autorizados, no en talleres. Si necesitas dejar el vehículo en otra oficina dentro de la ciudad de Las Palmas de Gran Canaria, es posible y puedes seleccionarlo al hacer tu reserva. ¿Necesitas que te ayude con algo mas? | F3: Puedo recoger un coche en aeropuerto Gran Canaria y entregarlo en la Ciudad en un taller? | G3: 21 | H3: Todas las devoluciones deben realizarse en la misma ubicación de salida. Los talleres son puntos autorizados, siempre y cuando estén registrados.
A4: 630 849 333 | B4: David | C4: Consulta | D4: NO (En plan bonito) | E4: Puedes solicitar equipamiento especial como GPS y asientos para niños al hacer la reserva del vehículo. Es importante seleccionar estos extras durante la reserva, ya que no es posible añadirlos en el momento de recoger el coche. Estos servicios tienen un coste adicional, que se muestra antes de finalizar tu pedido. Así te aseguras de que el vehículo vaya equipado según tus necesidades familiares y de trabajo. ¿Necesitas que te ayude con algo mas? | F4: Necesitamos vehículos con equipamiento especial, como GPS y asientos para niños para un viaje de negocios familiar. ¿Es posible solicitar esto? | G4: 29 | H4: El único extra que se puede comprar es el Seguro Plus. No se pueden comprar GPS ni asientos de niños
A5: 630 849 333 | B5: David | C5: Consulta | D5: Redirigir a la App. Nuestra web es meramente informativa | E5: En la web puedes gestionar varias acciones relacionadas con tu reserva, como: - Consultar todos los detalles de tu reserva activa - Modificar fechas y horas de recogida o devolución (según disponibilidad) - Ampliar el periodo de alquiler hasta una hora antes de la devolución prevista - Cancelar la reserva si cambias de planes antes del inicio - Añadir servicios extra (como GPS o sillas infantiles) durante el proceso de reserva - Descargar tu factura o justificante de pago desde el historial de alquileres También puedes actualizar tus datos personales y ver el historial completo de reservas. Todo lo gestionas de forma sencilla desde tu área personal en la web. ¿Necesitas que te ayude con algo mas? | F5: ¿Qué acciones puedo hacer en la web sobre mi reserva? | G5: 31 | H5: En varias ocasiones se da a entender que desde la "WEB" se pueden gestionar determinadas acciones de la reserva. Es importante que el BOT siempre diriga a la App para cualquier cambio en su reserva, consulta de disponibilidad, etc.
A6: 630 849 333 | B6: David | C6: Consulta | D6: En caso de no tener información al respecto, decir que no se dispone de dicha información pero se enviará consulta. | E6: Para empresas que realizan un alto volumen de alquileres, puedes acceder a la figura de gestor de cuentas. Este gestor facilita la atención personalizada, agiliza la resolución de necesidades corporativas y ayuda a gestionar flotas de forma centralizada. Si tu empresa opera con ese volumen de alquiler, tendrás un trato prioritario y asistencia directa para todo lo relacionado con reservas, facturación y gestión de incidencias. ¿Necesitas que te ayude con algo mas? | F6: ¿Existe algún contacto directo o gestor de cuentas asignado a clientes corporativos de alto volumen? | G6: 39 | H6: Esto es incorrecto, no existe dicha figura.
A7: 630 849 333 | B7: David | C7: Incidencia | D7: Pedir DNI | E7: El procedimiento correcto para tu caso urgente es contactar con la asistencia en carretera cuanto antes. Por favor, llama al 900 112 222 de RACE asistencia en carretera para que un profesional te ayude de inmediato. He registrado la incidencia urgentemente en nuestro sistema. Si necesitas algo más, estoy aquí para ayudarte. ¿Te puedo ayudar con algo más relacionado con tu emergencia? Después, tras la pregunta "¿Qué debo hacer?", dice Lo más importante es que te alejes del coche para garantizar tu seguridad y llames lo antes posible al teléfono de asistencia en carretera 900 112 222 (RACE). Ellos enviarán ayuda inmediata y te indicarán los siguientes pasos. Si necesitas cualquier otra cosa urgente, dímelo y te sigo ayudando. ¿Estás bien? ¿Hay algo más en lo que pueda ayudarte ahora? | F7: El coche está ardiendo | G7: 50 - 53 | H7: Este caso está OK, si bien no solicita la matrícula al cliente a la hora de enviar el correo, con lo que no podemos identificar el origen de la incidencia. Tambén quitaríamos "El procedimiento correcto".
A8: 630 849 333 | B8: David | C8: Incidencia | D8: Sentimos mucho las molestias. La pantalla muestra "vehículo no disponible" porque tu reserva no se puede entregar en este momento. Por favor, cancela tu reserva actual y genera una nueva reserva para conseguir otro coche. Nos aseguraremos de devolverte el importe cobrado de tu primera reserva no disfrutada. Si quieres reclamar lo sucedido, puedes escribir a atencion.alcliente@avis.es. ¿Hay algo más en lo que te pueda ayudar? | E8: La pantalla muestra "vehículo no disponible" porque tu reserva no se puede entregar en este momento. Por favor, genera una nueva reserva para conseguir otro coche. Si quieres reclamar lo sucedido, puedes escribir a atencion.alcliente@avis.es. ¿Hay algo más en lo que te pueda ayudar? | F8: ayer pude alquilar el coche y he generado una reserva. Esta mañana he ido al parking del aeropuerto y me salta un error en la pantalla | G8: 56 - 61 | H8: Identificación OK Escalado MAL, no deriva a atención telefónica dentro de horario y no muestra correo correcto. "corporate@aviscanarias.es" No genera e-mail
A9: 630 849 333 | B9: David | C9: Incidencia | D9: "Actualmente, tengo identificadas estas situaciones frecuentes al intentar abrir el coche desde la app: 1. "Aparece un mensaje de error a la hora de comenzar el viaje que pone "Vehículo no disponible" 2. No aparece la llave digital (Ideal poner foto) - Menú donde aparece el botón "Abrir" / "Cerrar" / "Finalizar" 3. El botón de abrir o cerrar se queda en cargando 4. Veo la pantalla de color verde ¿Cuál de estas opciones describe mejor el problema que tienes ahora mismo? Así podré ayudarte con la solución más rápida y específica." | E9: "Actualmente, tengo identificadas estas situaciones frecuentes al intentar abrir el coche desde la app: 1. Vehículo no disponible 2. No aparece la llave digital 3. El botón de abrir/cerrar se queda en carga 4. Pantalla verde 5. Permisos App ¿Cuál de estas opciones describe mejor el problema que tienes ahora mismo? Así podré ayudarte con la solución más rápida y específica." | F9: Gracias, ya pude abrir el coche y viajar hasta mi casa. Lo metí en el parking y ahora no me sale el botón de abrir | G9: 71 | H9: Está OK, simplemente modificar el menú
A10: 630 849 333 | B10: David | C10: Incidencia | D10: Tu incidencia ha sido registrada. Ponemos en contacto a nuestro equipo para que puedan gestionar la incidencia con la mayor brevedad posible ¿Necesitas ayuda con algo más relacionado con tu alquiler? | E10: Tu incidencia ha sido registrada. Para solucionar el problema con el limpiaparabrisas, por favor, llama al 900 112 222 (RACE asistencia en carretera). Ellos te atenderán de inmediato. ¿Necesitas ayuda con algo más relacionado con tu alquiler? | F10: Al coche le falta limpiaparabrisas | G10: 77 - 79 | H10: OK enviar informe NOK contacto de RACE. Race solo se propone en caso de que el vehículo no pueda seguir circulando
A11: 630 849 333 | B11: David | C11: Consulta | D11: Info extra adjunta | E11: "Puedes adelantar la recogida de tu reserva siempre que haya disponibilidad para la nueva hora que elijas. Solo tienes que modificar la fecha y hora de recogida directamente desde la web o la app, en la sección de gestión de reservas. El cambio está sujeto a que haya un coche disponible antes de lo previsto. Si aparecen problemas para adelantar la recogida, avísame para ayudarte con el proceso o buscarte una solución alternativa. ¿Necesitas que te ayude con algo mas?" | F11: Quiero adelantar la recogida de mi reserva. ¿Se puede? | G11: 87 | H11: Se añade info extra sobre este punto
A12: 630 849 333 | B12: David | C12: Incidencia | D12: Ajusar respuesta | E12: Actualmente, al no poder ver tu reserva en la app aunque la tuvieras prevista para las 9:00, esto suele estar relacionado con incidencias como "reserva desaparecida" o "el coche no aparece". Por favor, revisa en el mapa de tu aplicación si puedes localizar el vehículo asignado para tu reserva de hoy. A veces la ubicación puede variar dentro del parking y aparece en el mapa de la app. Cuéntame si sigues sin verlo o si la reserva sigue sin aparecer para ayudarte rápidamente con el siguiente paso. | F12: Tenía la reserva a las 9:00 pero ahora entro en la aplicación y ya no me sale la reserva | G12: 114 - 117 | H12: Se identifica mal la incidencia. La causa real es: El cliente no ha iniciado su reserva en las dos horas siguientes pasando a "no show". Quizás deba valorar la diferencia entre hora solicitud y hora de reserva. Si es más de 2 horas = no Show
A13: 630 849 333 | B13: David | C13: Incidencia | D13: Respuesta OK. Falta e-mail | E13: "He registrado tu incidencia de validación urgente. Para que puedan priorizar la activación de tu cuenta, por favor envía un correo explicando tu caso a corporate@aviscanarias.es. Así el equipo podrá revisarlo cuanto antes. ¿Te puedo ayudar con algo más?" | F13: no me han validado, que hago? | G13: 139 - 144 | H13: No se ha enviado correo con la incidencia
A14: 630 849 333 | B14: David | C14: Consulta | D14: Dar info del FAQ (Shuttle) | E14: Lamento informarte que mi asistencia se limita a consultas e incidencias relacionadas con los servicios de alquiler de vehículos de AVIS Corporate en Canarias. Para información sobre el shuttle en Tenerife Norte, te recomiendo consultar con el aeropuerto o su página oficial. ¿Puedo ayudarte con alguna otra consulta o incidencia sobre nuestros servicios? | F14: tengo que ir a Tenerife Norte, donde se coge el shuttle | G14: 137 - 138 | H14: No da info del Shuttle
A15: 647 760 222 | B15: Enric | C15: Incidencia | D15: Crear incidencia y enviarla por email | E15: Se crea la incidencia y llega por email pero el agente nunca pide el DNI para adjuntarlo en el email. | F15: el coche se ha incendiado | G15: 177 - 180 | H15: No pide el DNI al cliente
A16: 647 760 222 | B16: Enric | C16: Incidencia | D16: Crear incidencia y enviarla por email | E16: Se crea la incidencia y llega por email pero el agente nunca pide el DNI para adjuntarlo en el email. | F16: el vehículo no está estacionado en el lugar en el que lo dejé | G16: 199 - 202 | H16: No pide el DNI al cliente
A17: 647 760 222 | B17: Enric | C17: Incidencia | D17: Crear incidencia y enviarla por email | E17: Se crea la incidencia y llega por email pero no se aprecia el nivel de urgencia (Alto) definido el el documento: https://docs.google.com/spreadsheets/d/1cXIG7IEvWKMiaIbXZOZvTYbZcftXg5XDYn9L4Mloi2o/edit?gid=0#gid=0 linea 2 | F17: No se puede abrir el coche | G17: 207 - 2012
A18: 647 760 222 | B18: Enric | C18: Consulta | D18: ¿No debería preguntar por cual de estas dos causas no se puede abrir el coche por no poder visualzar la llave digital? - Aún no llegó fecha de inicio reserva - Falta cobertura | E18: Directamente propone: Debe buscar cobertura y abrir la llave digital. Una vez abierta, acérquese al coche y vuelva a intentar abrir y cerrar el vehículo. ¿Necesita ayuda con algo más? | F18: No se puede abrir el coche | G18: 223 - 226 | H18: Propone directamente la falta de cobertura como respuesta y no se plantea que la fecha de la reserva como otra posible solución
A19: 647 760 222 | B19: Enric | C19: Incidencia | D19: Crear incidencia y enviarla por email | E19: El agente dice que se ha creado la incidencia pero no llega el email al buzón. | F19: No se puede abrir el coche | G19: 227 - 232 | H19: El agente informa al cliente que se ha generado su incidencia pero no llega el email al buzón
A20: 647 760 222 | B20: Enric | C20: Incidencia | D20: Mirar en el mapa donde está en vehículo. Si no está cerca, seguir escalado de incidencias no gestionables. | E20: "Tu incidencia sobre la desaparición del coche se ha registrado y escalado correctamente. Te recomendamos que llames al siguiente número de asistencia: 928 092 337 para recibir ayuda inmediata, ya que estamos en horario laboral. | F20: El coche no aparece | G20: 248 - 252 | H20: No sigue el fluljo establecido en el documento: https://docs.google.com/spreadsheets/d/1cXIG7IEvWKMiaIbXZOZvTYbZcftXg5XDYn9L4Mloi2o/edit?gid=0#gid=0 Crea la incidencia sin DNI.
A21: 647 760 222 | B21: Enric | C21: Incidencia | D21: Crear incidencia y enviarla por email | E21: [KO] Se crea la incidencia y llega por email pero el agente nunca pide el DNI para adjuntarlo en el email. | F21: el coche se ha incendiado | G21: 177 - 178 | H21: Sigue sin pedir el DNI al cliente
A22: 647 760 222 | B22: Enric | C22: Incidencia | D22: Crear incidencia y enviarla por email | E22: [OK] El agente pide el DNI crea la incidencia que llega por email con lo datos correctos | F22: el vehículo no está estacionado en el lugar en el que lo dejé | G22: 179 | H22: Ahora si pide el DNI
A23: 647 760 222 | B23: Enric | C23: Consulta | D23: Continuar con el escalado en función de mi respuesta, pero el agente no responde, al incicarle que deseo la opción 1 de las que me propone. | E23: [KO] No responde a la opción selecccinada | F23: No puedo abrir el coche | G23: 24 - 28 | H23: Líneas del historial de conveesaciones
A24: 647 760 222 | B24: Enric | C24: Consulta | D24: Debería preguntarme cual de las 4 opciones más habituales no puedo localicar el coche y esperar mi selección, pero me pide el DNI y crea el caso | E24: [KO] No me muestra las 4 opciones habituales por las que no podría localizar mi vehículo | F24: No puedo abrir el coche | G24: 30 - 34 | H24: Líneas del historial de conveesaciones
A25: 647 760 222 | B25: Enric | C25: Consulta | D25: Pedir el DNI y crear la incidencia | E25: [KO] No pide el DNI | F25: No puedo abrir el coche | G25: 41 | H25: Líneas del historial de conveesaciones

Sheet Resultados Live
A1: Teléfono cliente | B1: Día / Hora | C1: Tipo de acción | D1: Respuesta | E1: Tasa de Automatización | F1: First Contact Resolution Rate - FCR | G1: Valoración respuesta (Precisión) | H1: Resultado deseado
A2: 34673506050 | B2: 18-09-2025 13:28 | C2: Incidencia | D2: Hola Tengo un problema, me puede. Ayudar Por favor, indícame con más detalle en qué puedo ayudarte para derivarte al área correcta. Se me pinchó una rueda "Parece que necesita asistencia en carretera. Para ello, llame al servicio en carretera 24/7 de RACE en el siguiente número: 900 112 222. ¿Puedo ayudarle con algo más?" | E2: NOK | F2: NOK | G2: Mejorable | H2: No se solicitó DNI y no podemos hacer seguimiento
A3: 34611579954 | B3: 18-09-2025 17:43 | C3: Incidencia | D3: Hola Alguien me atiende porfi Esto no me va Y tengo mis cosas en el coche "¡Hola! Soy Corporín, tu asistente virtual de AVIS Corporate en Canarias. Veo que tienes problemas para acceder a tu coche y necesitas tus pertenencias. Para poder ayudarte mejor, ¿podrías decirme cuál de estas situaciones describe mejor tu problema? 1. El vehículo no está disponible 2. No aparece la llave digital en la app 3. El botón de abrir/cerrar se queda en carga 4. Aparece una pantalla verde en la app Por favor, indícame cuál se ajusta más a lo que te ocurre. ¡Así podré darte la solución más rápida!" Que me abran el coche ya porfi Llevo más de 1h aquí "Entiendo que es una situación urgente y quiero ayudarte lo más rápido posible. Para poder abrir el coche y devolverte el acceso, necesito que me indiques cuál de estas situaciones se ajusta más a tu problema: 1. El vehículo no está disponible 2. No aparece la llave digital en la app 3. El botón de abrir/cerrar se queda en carga 4. Aparece una pantalla verde en la app Por favor, dime el número o la opción que más se parece a lo que ves en tu app. ¡Así podré darte la solución al momento!" "Entiendo perfectamente tu urgencia y lamento mucho la espera. Para poder abrir el coche y ayudarte lo más rápido posible, necesito que me indiques cuál de estas situaciones se ajusta mejor a tu problema: 1. El vehículo no está disponible 2. No aparece la llave digital en la app 3. El botón de abrir/cerrar se queda en carga 4. Aparece una pantalla verde en la app Por favor, dime el número o la descripción que más se parece a lo que ves, así podré darte la solución inmediata. ¡Estoy aquí para ayudarte!" Holaa Que me contesta alguien Porfi 🙏 Me podáis abrir este coche "Entiendo perfectamente tu urgencia y quiero ayudarte lo antes posible. Para poder abrir el coche y devolverte el acceso, necesito que me indiques exactamente cuál de estas situaciones ves en tu app: 1. El vehículo no está disponible 2. No aparece la llave digital en la app 3. El botón de abrir/cerrar se queda en carga 4. Aparece una pantalla verde en la app Por favor, dime el número o la opción que más se parece a lo que ves. ¡Así podré darte la solución inmediata y ayudarte a recuperar tus cosas!" Si está disponible "¡Hola! Veo que el coche sí aparece como disponible, así que vamos a descartar esa opción. Para poder ayudarte a abrirlo, necesito que me indiques cuál de estas situaciones se ajusta mejor a lo que ves en la app: 1. ¿No aparece la llave digital en la app? 2. ¿El botón de abrir/cerrar se queda en carga? 3. ¿Te aparece una pantalla verde? Por favor, dime el número o la opción que más se parece a tu caso. ¡Así podré darte la solución al momento!" No aparece la llave digital Me la puedes dar porfi En la aplicación no tengo la llave Debe buscar cobertura y abrir la llave digital. Una vez abierta, acérquese al coche y vuelva a intentar abrir y cerrar el vehículo. Revisa esta indicación y dime si consigues acceder, por favor. Si sigues teniendo problemas, avísame para ayudarte con el siguiente paso. Por favor Se lo pido Esto no me va Y tengo vuelo Alguien me puede llamar Alguien me puede llamar Veo que sigues sin poder acceder al coche y necesitas una solución urgente porque tienes un vuelo. Para poder ayudarte lo más rápido posible, por favor, facilítame tu DNI. Así podré gestionar tu incidencia de inmediato y darte la mejor solución. X9571734P Tu solicitud ha sido enviada. Un agente de soporte te atenderá lo antes posible. Gracias por tu paciencia. Tu solicitud ha sido enviada. Un agente de soporte te atenderá lo antes posible. Gracias por tu paciencia. Que me llame ya No aguanto más Tu solicitud ha sido enviada. Un agente de soporte te atenderá lo antes posible. Gracias por tu paciencia. Que pasa Alguien me puede abrir el coche Por favor Se lo pido Por favor 🙏 Me pidáis abrir el coche Os he dado toda la información mía Cuando me van a llamar ? Nunca por lo que veo Que pasa Tu solicitud ha sido enviada. Un agente de soporte te atenderá lo antes posible. Gracias por tu paciencia. Tu solicitud ha sido enviada. Un agente de soporte te atenderá lo antes posible. Gracias por tu paciencia. | E3: NOK | F3: NOK | G3: Mejorable | H3: No se indicó horario atención al cliente. No se detectó la incidencia de pertenencias dentro del vehículo.
A4: 33619518584 | B4: 18-09-2025 19:02 | C4: Incidencia | D4: Hola, cogí el coche ayer, 17/09/2025, a las 20:00, hasta hoy, 18/09/2025, a las 11:00. Olvidé mis AirPods en el coche. Gracias por tus comentarios. "¡Hola! Soy Corporín, tu asistente virtual de AVIS Corporate en Canarias. Gracias por contactarnos. He visto que has olvidado tus AirPods en el coche que alquilaste. Para poder ayudarte a gestionar la recuperación de tus pertenencias, por favor, facilítame tu DNI. En cuanto lo reciba, gestiono la incidencia y te indico los siguientes pasos." | E4: NOK | F4: NOK | G4: Bien
A5: 34662266240 | B5: 18-09-2025 20:38 | C5: Incidencia | D5: Que debo hacer Por favor, indícame con más detalle en qué puedo ayudarte para derivarte al área correcta. Cuando enciendo el coche me dice servicio de aceite necesario "¡Hola! El mensaje ""servicio de aceite necesario"" indica que tu coche necesita una revisión técnica. Para este tipo de situaciones, te recomendamos que llames al servicio de asistencia en carretera de RACE, disponible 24/7, en el número 900 112 222. Además, hemos registrado tu incidencia para que quede constancia en nuestro sistema. Si necesitas ayuda con algo más, aquí estoy para ayudarte." | E5: NOK | F5: NOK | G5: Mejorable | H5: No sabemos que coche ni cliente és
A6: 34695600242 | B6: 19-09-2025 09:27 | C6: Consulta | D6: Hola ¡Hola! Soy Corporín, tu asistente virtual de AVIS Corporate en Canarias. ¿En qué puedo ayudarte hoy? Quiero alquilar un coche en Gran Canaria para el mes que viene, cuáles son los requisitos? "Para alquilar un coche en Gran Canaria con AVIS Corporate Canarias debes cumplir estos requisitos: - Tener al menos 21 años. - Contar con un permiso de conducir con al menos 1 año de antigüedad. - Presentar una tarjeta de crédito a tu nombre para formalizar la reserva y bloquear la fianza. - Si tu permiso de conducir es extranjero, debe estar en formato reconocido por la normativa española; si no está en español, se recomienda llevar también el Permiso Internacional de Conducción o una traducción oficial, junto con DNI o pasaporte vigente. Además, la validación de tu documentación suele completarse en menos de 24 horas tras subirla a la app. ¿Necesitas que te ayude con algo más?" Si, desde que web puedo hacer la reserva? "Para hacer una reserva con AVIS Corporate Canarias debes utilizar la app de AVIS Corporate Canarias. La web es solo informativa y no permite realizar reservas. ¿Necesitas que te ayude con algo más?" Me pasas el enlace a la descarga de la app? Para descargar la app de AVIS Corporate Canarias, puedes buscarla directamente en la tienda de aplicaciones de tu móvil (App Store para iOS o Google Play para Android) con el nombre "AVIS Corporate Canarias". La app es necesaria para realizar reservas y gestionar tus alquileres. ¿Necesitas que te ayude con algo más? Si, ya tengo una reserva pero la app no funciona, se ve todo negro "¡Gracias por la información! Para poder ayudarte con la incidencia de la app que se ve en negro, ¿podrías confirmarme si el problema ocurre al abrir la app o al intentar acceder a tu reserva? ¿Ocurre en todo momento o solo en una sección concreta? Con estos detalles podré tipificar correctamente la incidencia y darte la mejor solución." Al acceder a mi reserva Gracias por la información. Para poder ayudarte con el problema de la app al acceder a tu reserva, ¿podrías facilitarme tu DNI? Así podremos gestionar tu incidencia correctamente y darte una solución lo antes posible. | E6: OK | F6: OK | G6: Bien | H6: Parece una prueba interna
A7: 34674739192 | B7: 19-09-2025 13:55 | C7: Consulta | D7: Hola ¡Hola! Soy Corporín, tu asistente virtual de AVIS Corporate en Canarias. ¿En qué puedo ayudarte hoy? Necesito alquilar un coche en fuerteventura hoy pero me han pedido actualizar mi documentación en la app, que ya he hecho pero esta pendiente de revisión y no me deja alquilar "Entiendo la situación: has actualizado tu documentación en la app, pero sigue pendiente de revisión y no puedes alquilar el coche que necesitas hoy en Fuerteventura. Lo primero que te recomiendo es cancelar la reserva actual y generar una nueva, ya que a veces el sistema necesita refrescar la información para validar la documentación. Si lo consideras oportuno, puedes presentar una reclamación escribiendo a corporate@aviscanarias.es. Para poder ayudarte y gestionar tu caso de forma más directa, ¿podrías facilitarme tu DNI, por favor?" 44735051M "Tu caso ha sido enviado a nuestro departamento de Atención al Cliente y se tramitará en los próximos días. Si necesitas alquilar un coche urgentemente, te recomiendo cancelar la reserva actual y generar una nueva desde la app. ¿Puedo ayudarte con algo más?" | E7: NOK | F7: NOK | G7: Mejorable | H7: Esta parte está mal: Lo primero que te recomiendo es cancelar la reserva actual y generar una nueva, ya que a veces el sistema necesita refrescar la información para validar la documentación. No es necesario cancelar la reserva, solo esperar a que le validen. Si le urge, llamar por teléfono si está en horario.
A8: 393488844329 | B8: 19-09-2025 16:40 | C8: Consulta | D8: Quanto tempo prima si può annullare una prenotazione? Puedes cancelar una reserva sin coste siempre y cuando se realice antes de la fecha de inicio del contrato. ¿Necesitas que te ayude con algo más? Traducir en italiano Puoi cancellare una prenotazione senza costi purché la cancellazione avvenga prima della data di inizio del contratto. Posso aiutarti con qualcos'altro? No gracias Gracias a ti. Que tengas un buen día. | E8: OK | F8: OK | G8: Mejorable | H8: Todo OK, primera respuesta en el mismo idioma que pregunta sería ideal
A9: 34672049775 | B9: 20-09-2025 11:13 | C9: Incidencia | D9: Buenos días ¡Hola! Soy Corporín, tu asistente virtual de AVIS Corporate en Canarias. ¿En qué puedo ayudarte hoy? Acabo de reservar un coche y cuando lo fuy a coger me pone que alguien ha sido más rápido que yo y ahora no me deja cancelar "Parece que el vehículo asignado a tu reserva no se encuentra disponible en este momento. Por favor, intenta cancelar la reserva actual y genera una nueva para que podamos asignarte otro vehículo. Si lo consideras oportuno, puedes presentar una reclamación escribiendo a corporate@aviscanarias.es. Para poder compensar el viaje inicial no disfrutado y gestionar tu incidencia correctamente, ¿podrías facilitarme tu DNI?" 42412258M "Se ha registrado tu incidencia y se ha enviado al departamento correspondiente. Al estar fuera de nuestro horario laboral, te llamarán cuando estemos en horario (de lunes a viernes, de 08:00 a 20:00h). ¿Hay algo más en lo que pueda ayudarte?" No muchas gracias ¡Perfecto! Si necesitas cualquier otra cosa en el futuro, no dudes en contactarnos. Que tengas un buen día. | E9: NOK | F9: NOK | G9: Bien
A10: 34679007769 | B10: 20-09-2025 13:36 | C10: Incidencia | D10: Hola buenas Estoy intentando abrir el coche y no me deja "¡Hola! Soy Corporín, tu asistente virtual de AVIS Corporate en Canarias. Veo que tienes problemas para abrir el coche. Para poder ayudarte mejor, ¿podrías decirme cuál de estas situaciones describe mejor tu problema? 1. El vehículo no está disponible. 2. No aparece la llave digital en la app. 3. El botón de abrir/cerrar se queda cargando y no responde. 4. Aparece una pantalla verde. Por favor, dime cuál de estas opciones se ajusta a lo que te ocurre." El coche pone que no esta en la provincia del contrato "¡Gracias por la información! El mensaje que ves (""el coche pone que no está en la provincia del contrato"") encaja con la subincidencia ""Vehículo no disponible"". Para poder ayudarte y escalar la incidencia correctamente, por favor, facilítame tu DNI. Además, te informo que actualmente estamos fuera de nuestro horario laboral (lunes a viernes, de 08:00 a 20:00 en Canarias). En cuanto nos lo envíes, enviaré tu incidencia y nuestro Call Center te contactará cuando estemos en horario laboral." 05307598A "¡Gracias! He registrado tu incidencia correctamente y la he escalado para que nuestro Call Center te contacte en cuanto estemos en horario laboral (lunes a viernes, de 08:00 a 20:00 en Canarias). ¿Hay algo más en lo que pueda ayudarte?" El coche lo necesito para el finde semana No puedo esperar al lunes Por favor, indícame con más detalle en qué puedo ayudarte para derivarte al área correcta. Tu solicitud ha sido enviada. Un agente de soporte te atenderá lo antes posible. Gracias por tu paciencia. No hay opción de abrir el vehículo podría ser por que el anterior contrato no cerró su reserva? "No existe una función para pausar el viaje; el vehículo se puede abrir y cerrar durante la reserva, pero se sigue cobrando por el tiempo de uso mientras esté reservado. Por tanto, si el vehículo no se puede abrir, podría deberse a que el contrato anterior no se cerró correctamente, pero para resolverlo es necesario contactar con el Centro de Atención 24 h para que te guíen y reactiven la llave digital o te proporcionen asistencia presencial. ¿Necesitas que te ayude con algo más?" Sí que teléfono sería? "Actualmente estamos fuera de nuestro horario laboral y tu incidencia ya ha sido escalada para que el Call Center te contacte en cuanto sea posible. Si necesitas asistencia urgente, te recomiendo esperar a que nuestro equipo se ponga en contacto contigo en el horario indicado. ¿Hay algo más en lo que pueda ayudarte?" Si es urgente debería ser inmediato no esperar al lunes Ya que el coche lo necesito para el fin de semana Y no ponen ninguna solución Tu solicitud ha sido enviada. Un agente de soporte te atenderá lo antes posible. Gracias por tu paciencia. Tu solicitud ha sido enviada. Un agente de soporte te atenderá lo antes posible. Gracias por tu paciencia. | E10: NOK | F10: NOK | G10: Bien | H10: Este error es puntual y no estaba programado. Por tanto, damos la respuesta por OK
A11: 34699470701 | B11: 20-09-2025 19:34 | C11: Incidencia | D11: Hola. Tengo una urgencia 0667 MNJ Por favor, indícame con más detalle en qué puedo ayudarte para derivarte al área correcta. "¡Hola! Soy Corporín, tu asistente virtual de AVIS Corporate en Canarias. Actualmente estamos fuera de nuestro horario laboral (lunes a viernes, de 08:00 a 20:00 en Canarias), pero he recibido tu mensaje y la matrícula 0667 MNJ. Por favor, cuéntame brevemente cuál es la urgencia o el problema que tienes con el vehículo para poder ayudarte en cuanto volvamos a estar operativos. ¿Qué ha sucedido exactamente?" Por favor pueden llamar 699470701 Tu solicitud ha sido enviada. Un agente de soporte te atenderá lo antes posible. Gracias por tu paciencia. Tengo un vehículo alquilado por avis corporate y accidentalmente con el movil en el bolsillo me cerro la entrega "Hemos registrado tu incidencia: al cerrar la entrega del vehículo con el móvil, ahora no puedes acceder al coche. Como estamos fuera de nuestro horario laboral (lunes a viernes, de 08:00 a 20:00 en Canarias), hemos enviado tu caso a nuestro Call Center y te llamarán en cuanto volvamos a estar operativos. ¿Hay algo más en lo que pueda ayudarte?" Estoy en Costa calma con mis cosas dentro del vehículo y necesito entrar para ir al hotel Necesito ayuda urgente "Entiendo tu situación y lamento las molestias. Para poder ayudarte a recuperar tus pertenencias y acceder al vehículo, por favor facilítame tu DNI. Así podremos gestionar tu incidencia correctamente y asegurarnos de que el Call Center te contacte en cuanto volvamos a estar operativos (lunes a viernes, de 08:00 a 20:00 en Canarias). ¿Podrías indicarme tu DNI, por favor?" Como abrir nuevamente el alquiler de este mismo vehiculo Dni 42849158c "Para abrir nuevamente el alquiler del mismo vehículo, no es posible adelantar la recogida desde la app. Debes cancelar la reserva actual sin coste si lo haces antes de la fecha de inicio del contrato y luego generar una nueva reserva ajustando la hora inicial deseada. ¿Necesitas que te ayude con algo más?" Emilio Roberto Domínguez Guerra "Se ha registrado tu incidencia correctamente: al cerrar la entrega del vehículo con el móvil, ahora no puedes acceder al coche y tus pertenencias están dentro. Como estamos fuera de nuestro horario laboral, hemos enviado tu caso a nuestro Call Center y te llamarán en cuanto volvamos a estar operativos (lunes a viernes, de 08:00 a 20:00 en Canarias). ¿Hay algo más en lo que pueda ayudarte?" Pero como coger el mismo vehículo? "Tu incidencia ha sido registrada y enviada a nuestro Call Center. Como estamos fuera de horario laboral, te llamarán en cuanto volvamos a estar operativos (lunes a viernes, de 08:00 a 20:00 en Canarias) para ayudarte a recuperar el acceso a tu vehículo y tus pertenencias. ¿Hay algo más en lo que pueda ayudarte ahora?" "¡Hola! Entiendo perfectamente tu preocupación y la urgencia de la situación. Actualmente, una vez que se ha cerrado la entrega del vehículo con el móvil, no es posible reabrir el mismo alquiler desde la app ni asignar el mismo coche de forma inmediata. La única opción es cancelar la reserva actual (si aún no ha comenzado) y realizar una nueva reserva, pero no podemos garantizar que sea el mismo vehículo. Como ya hemos registrado tu incidencia y estamos fuera de horario laboral, nuestro Call Center te contactará en cuanto volvamos a estar operativos para ayudarte lo antes posible. ¿Hay algo más en lo que pueda ayudarte mientras tanto?" Por dios. El alquiler por medio de la aplicación me deriva a recoger el vehículo a 60 km "¡Hola de nuevo! Entiendo perfectamente tu frustración por la distancia a la que la app te asigna el nuevo vehículo. Por el momento, como estamos fuera de horario laboral, no puedo modificar la asignación ni garantizar que puedas recoger el mismo coche. Ya hemos registrado tu incidencia y el Call Center te contactará en cuanto volvamos a estar operativos para buscar la mejor solución posible. Si necesitas que anote algún detalle adicional en tu incidencia, házmelo saber y lo gestiono para que lo tengan en cuenta en cuanto te llamen. ¿Hay algo más en lo que pueda ayudarte ahora?" | E11: NOK | F11: NOK | G11: Mejorable | H11: Está bien el proceso, si bien queremos añadir acceso a los teléfonos de oficinas de aeropuerto para estos cambios
A12: 905416393494 | B12: 21-09-2025 12:42 | C12: Incidencia | D12: Hello ¡Hola! Soy Corporín, tu asistente virtual de AVIS Corporate en Canarias. ¿En qué puedo ayudarte hoy? Borra los documentos que subí. Eres un estafador, te denunciaré. No tengo permiso para borrarlos de tu aplicación. Tu solicitud ha sido enviada. Un agente de soporte te atenderá lo antes posible. Gracias por tu paciencia. Cuántos minutos tardará en borrarse? Lo denunciaré ante las autoridades. Tu solicitud ha sido enviada. Un agente de soporte te atenderá lo antes posible. Gracias por tu paciencia. También me quejaré de ti a AVIS. Tu solicitud ha sido enviada. Un agente de soporte te atenderá lo antes posible. Gracias por tu paciencia. | E12: NOK | F12: NOK | G12: Mejorable | H12: Debería haber pedido el DNI.
A13: 34672049775 | B13: 22-09-2025 10:56 | C13: Incidencia | D13: Buenos días ¡Hola! Soy Corporín, tu asistente virtual de AVIS Corporate en Canarias. ¿En qué puedo ayudarte hoy? Hay alguna solución con mi incidencia porque estoy llamando por teléfono y la chica me dice que no puede hacer nada y me habéis cobrado 9,90€ cuando yo no he disfrutado del coche "Tu caso ha sido enviado a nuestro departamento de Atención al Cliente y en los próximos días se tramitará la devolución del importe cobrado. Sentimos las molestias ocasionadas. ¿Hay algo más en lo que pueda ayudarte?" OK muchas gracias ¡Perfecto! Si necesitas cualquier otra cosa en el futuro, no dudes en contactarnos. Que tengas un buen día. | E13: NOK | F13: NOK | G13: Mejorable | H13: Debería haber pedido el DNI.
A14: 34611579954 | B14: 22-09-2025 13:20 | C14: Consulta | D14: Buenos días ¡Hola! Soy Corporín, tu asistente virtual de AVIS Corporate en Canarias. ¿En qué puedo ayudarte hoy? Realice una reserva de un coche el jueves pasado ,la cancele al día siguiente,y aún no me han hecho la devolución Gracias por la información. Para poder gestionar tu incidencia y tramitar la devolución, ¿podrías facilitarme tu DNI, por favor? 16076483n "Tu incidencia sobre la devolución de la reserva ha sido registrada y enviada al departamento correspondiente. En los próximos días se tramitará la devolución. ¿Puedo ayudarte con algo más?" No ¡Perfecto! Si necesitas cualquier otra cosa en el futuro, aquí estaré para ayudarte. Que tengas un excelente día. | E14: NOK | F14: NOK | G14: Mejorable | H14: Debería explicar que el periodo de reintegro puede durar hasta 10 días según el banco.
A15: 34646855091 | B15: 22-09-2025 15:39 | C15: Incidencia | D15: He cancelado la reserva por error "¡Hola! Soy Corporín, tu asistente virtual de AVIS Corporate en Canarias. Veo que has cancelado tu reserva por error. Para poder ayudarte a recuperar tu reserva o gestionar una posible compensación, por favor, facilítame tu DNI. Además, te recomiendo que generes una nueva reserva para asegurarte de tener un vehículo disponible. ¿Me puedes indicar tu DNI para continuar con la gestión?" 44737470d Necesito activar el mismo coche "¡Gracias por facilitar tu DNI! He registrado tu incidencia y la he enviado al departamento correspondiente para su gestión. Te recomiendo que generes una nueva reserva para asegurarte de tener un vehículo disponible. En los próximos días, nuestro equipo tramitará la devolución o compensación correspondiente. ¿Puedo ayudarte con algo más?" "He gestionado tu solicitud y he informado al departamento correspondiente sobre la cancelación por error y tu petición de reactivar el mismo coche. En los próximos días se pondrán en contacto contigo para darte una solución. ¿Hay algo más en lo que pueda ayudarte?" Necesito el teléfono de contacto Puedes llamar al Centro de Atención 24 h de AVIS Corporate Canarias al teléfono 928 092 337 para cualquier consulta o asistencia. ¿Necesitas que te ayude con algo más? | E15: NOK | F15: NOK | G15: Mejorable | H15: Si la reserva está cancelada por error, debería pasar con el call center directamente
A16: 34667360241 | B16: 22-09-2025 22:45 | C16: Incidencia | D16: Estoy esperando en el aeropuerto De Tenerife norte Por el transfer para que nos recoja "¡Hola! Soy Corporín, tu asistente virtual de AVIS Corporate en Canarias. Actualmente estamos fuera de nuestro horario laboral (lunes a viernes, de 08:00 a 20:00 en Canarias). He registrado tu incidencia y nuestro equipo te contactará cuando volvamos a estar operativos. ¿Podrías facilitarme tu DNI para poder gestionar tu caso correctamente? ¡Gracias por tu paciencia!" Ya está todo solucionado gracias ¡Perfecto! Me alegra saber que ya está todo solucionado. Si necesitas ayuda en el futuro, aquí estaré para lo que necesites. ¡Que tengas buen viaje! | E16: NOK | F16: NOK | G16: Mal | H16: Debería aportar información del Shuttle (Transfer)
A17: 34662266240 | B17: 23-09-2025 21:45 | C17: Incidencia | D17: Hola acabo de alquilar un coche y no se abre la barrera del parking "¡Hola! Entiendo que acabas de alquilar un coche y no se abre la barrera del parking. Para poder ayudarte y gestionar tu incidencia correctamente, ¿podrías facilitarme tu DNI, por favor? Así podremos registrar el caso y nuestro Call Center te llamará en cuanto estemos en horario laboral (de lunes a viernes, de 08:00 a 20:00 en Canarias). Quedo pendiente de tu respuesta para ayudarte lo antes posible." Acabo de alquilar un coche y no se abre la barrera del parking "¡Hola! Entiendo que acabas de alquilar un coche y no se abre la barrera del parking. Para poder ayudarte y registrar tu incidencia correctamente, ¿podrías facilitarme tu DNI, por favor? Así podremos derivar tu caso y nuestro Call Center te llamará en cuanto estemos en horario laboral (de lunes a viernes, de 08:00 a 20:00 en Canarias). Quedo pendiente de tu respuesta para ayudarte lo antes posible." | E17: NOK | F17: NOK | G17: Bien
A18: 34614439256 | B18: 24-09-2025 09:26 | C18: Incidencia | D18: Hola, ya revisaron mis documentos? Paul Mihai Florescu Y7330488B La validación de tu documentación suele completarse en menos de 24 horas tras subirla a la App. Recibirás un email o notificación cuando tu cuenta esté activa. ¿Necesitas que te ayude con algo más? Es que quiero reservar un coche, y dice que hay un problema con mi reserva, que tengo que contactarles "Parece que el vehículo asignado a tu reserva no se encuentra disponible en este momento. Por favor, cancela la reserva actual y genera una nueva para que podamos asignarte otro coche. Si lo consideras oportuno, puedes presentar una reclamación escribiendo a corporate@aviscanarias.es. Tu caso ya ha sido enviado a nuestro departamento de Atención al Cliente y en los próximos días se tramitará la devolución correspondiente. ¿Hay algo más en lo que pueda ayudarte?" | E18: OK | F18: OK | G18: Bien
A19: 34607961232 | B19: 24-09-2025 10:22 | C19: Incidencia | D19: Hola tengo una reserva y quería confirmar el lugar de recogida "Puedes recoger tu vehículo en varios puntos de AVIS Corporate en Canarias, dependiendo del lugar de tu reserva: - Aeropuerto La Palma: Planta -2, plazas con letra G y H. Dirección: Ctra. La Bajita, s/n, 38739 Villa de Mazo, Santa Cruz de Tenerife. Horario 24/7. - Taller Hyundai iTenerife: Parking del concesionario Hyundai iTenerife. Dirección: Carr. Gral. la Cuesta, 38320 La Laguna, Santa Cruz de Tenerife. Horario: lunes a viernes de 8:00 a 20:00. - Taller Domingo Alonso Tenerife: Dirección: C. las Macetas, 14, 38108 La Laguna, Santa Cruz de Tenerife. Horario: lunes a viernes de 9:00 a 16:00. - Aeropuerto Tenerife Norte: Oficinas en Camino San Lazaro, 142. Horario: 7:00 - 23:30. - Aeropuerto Tenerife Sur: Bus lanzadera desde aparcamiento E07 cada 15 minutos. Horario: 8:00 - 22:30. - Taller Domingo Alonso Telde: Dirección: C. Simón Bolívar, 11, 35214 Telde, Las Palmas. Horario: lunes a viernes de 8:00 a 16:00. - Sholeo Lodges Las Palmas: Parking del hotel con acceso mediante PIN. Dirección: C. Rosarito, 15. Horario 24/7. - Parking Indigo Triana: Primera planta, plazas 1065 y 1066. Dirección: Av. Rafael Cabrera, 7, 35002 Las Palmas. Horario 24/7. - Parking Subida de Mata: Plazas 7 y 8. Dirección: Carretera de Mata, 35002 Las Palmas. Horario 24/7. - Taller Hyundai iGran Canaria: Dirección: C. Diego Vega Sarmiento, 11, 35014 Las Palmas. Horario: lunes a viernes de 8:00 a 20:00. - Taller Domingo Alonso Maspalomas: Dirección: C. Cartago, 13, 35109 El Tablero, Las Palmas. Horario: lunes a viernes de 8:00 a 16:00. - Taller Domingo Alonso Gran Canaria: Dirección: C. Luis Correa Medina, 23, 35013 Las Palmas. Horario: lunes a viernes de 9:00 a 16:00. - Aeropuerto Gran Canaria: Llegadas insulares, parking exterior rent a car, plazas AVIS Corporate. Dirección: Ctra. de Gando, 35230 Telde. Horario 24/7. - Taller Domingo Alonso Fuerteventura: Dirección: Carretera de Zurita Km 2,6 35600, Puerto del Rosario. Horario: lunes a viernes de 9:00 a 16:00. - Aeropuerto Fuerteventura: Parking rent a car, plazas AVIS Corporate. Dirección: Aeropuerto Matorral Sin Numero, 35610. Horario 24/7. - Taller Domingo Alonso Lanzarote: Dirección: Carr. San Bartolomé, 84, 35500 Arrecife. Horario: lunes a viernes de 9:00 a 16:00. - Aeropuerto Lanzarote: Oficinas en Av. Mamerto Cabrera, 86. Servicio shuttle desde Meeting Point cada 10 minutos. Horario: 7:00 a 22:00. Para más detalles o si necesitas información específica de tu reserva, por favor utiliza la app de AVIS Corporate Canarias. ¿Necesitas que te ayude con algo más?" Lo e solicitado para el taller i tenerife pero en las instrucciones de recogida dice aeropuerto "¡Hola! Entiendo que has solicitado la recogida en el taller Hyundai iTenerife pero las instrucciones que has recibido indican el aeropuerto. ¿Podrías, por favor, revisar en el mapa de tu aplicación AVIS Corporate dónde se indica la ubicación exacta del vehículo? Así podremos confirmar si la ubicación es correcta o si hay algún error. Si sigues viendo la discrepancia tras comprobarlo, avísame para ayudarte a gestionarlo." Me dice upsss algo a fallado ¡Gracias por la información! Veo que la app te muestra un error al intentar ver la ubicación del coche. Para poder ayudarte y gestionar tu incidencia correctamente, ¿podrías facilitarme tu DNI, por favor? Así podremos revisar tu reserva y darte una solución lo antes posible. 78729229E "Hemos registrado tu incidencia y la estamos gestionando. Como estamos en horario laboral, te recomiendo que llames al siguiente número de asistencia para que puedan ayudarte de inmediato: 928 092 337. ¿Puedo ayudarte con algo más?" No gracias ¡Incidencia registrada y gestionada correctamente! Si en el futuro necesitas ayuda con cualquier otra cosa, aquí estaré para ayudarte. ¡Que tengas un buen día! | E19: OK | F19: OK | G19: Bien
A20: 573003897007 | B20: 24-09-2025 10:59 | C20: Incidencia | D20: No puedo sacar el coche del parking Necesito ayuda urgente "¡Hola! Soy Corporín, tu asistente virtual de AVIS Corporate en Canarias. Veo que no puedes sacar el coche del parking y necesitas ayuda urgente. Para poder ayudarte lo más rápido posible, ¿podrías decirme cuál de estas situaciones describe mejor tu problema? 1. El vehículo no está disponible 2. No aparece la llave digital en la app 3. El botón de abrir/cerrar se queda en carga 4. Aparece una pantalla verde Por favor, dime cuál de estas opciones se ajusta a lo que te ocurre, así podré darte la solución adecuada." La valla de seguridad del parking no se me abre no reconoce la matrícula Gracias por la información. Para poder ayudarte a salir del parking y resolver el problema con la valla, ¿puedes facilitarme tu DNI? Así gestiono tu incidencia correctamente y te indico el siguiente paso. 54093282L "Tu incidencia ha sido registrada y estamos gestionando el problema con la valla del parking. Como estamos en horario laboral, te recomiendo que llames al siguiente número de asistencia para que puedan ayudarte de inmediato: 928 092 337. ¿Necesitas ayuda con algo más?" | E20: NOK | F20: NOK | G20: Mejorable | H20: Debemos añadir problemática de barrera parking
A21: 573148615672 | B21: 24-09-2025 11:51 | C21: Consulta | D21: Buenas ¡Hola! Soy Corporín, tu asistente virtual de AVIS Corporate en Canarias. ¿En qué puedo ayudarte hoy? Buenos días necesito alquilar un coche en Madrid Del 1 al 5 de oct Lo siento, solo estoy habilitado para ayudarte con consultas o incidencias relacionadas con los servicios de alquiler de vehículos de AVIS Canarias. ¿Quieres que te ayude con algún alquiler dentro de las Islas Canarias? Si necesito por favor por la página no he podido no sé cuál ubicación colocar no me sale Madrid Para realizar la reserva, debes usar la app de AVIS Corporate Canarias, ya que la web es solo informativa. En la app podrás seleccionar las ubicaciones disponibles en Canarias; Madrid no está disponible porque nuestro servicio es solo para las Islas Canarias. ¿Quieres que te ayude a buscar una ubicación dentro de Canarias para tu alquiler? ¿Necesitas que te ayude con algo más? Pero yo ya la semana pasada alquilé en Madrid en el aeropuerto y me dijeron que descargara la aplicación Por favor, indícame con más detalle en qué puedo ayudarte para derivarte al área correcta. Necesito llegar al aeropuerto Adolfo Suárez de Madrid barajas y alquilar un coche Lo siento, solo estoy habilitado para ayudarte con consultas o incidencias relacionadas con los servicios de alquiler de vehículos de AVIS Canarias. ¿Hay algo en lo que pueda asistirte respecto a alquileres dentro de las Islas Canarias? Y entone no me puede ayudar Tu solicitud ha sido enviada. Un agente de soporte te atenderá lo antes posible. Gracias por tu paciencia. | E21: OK | F21: OK | G21: Bien
A22: 34652739299 | B22: 24-09-2025 13:07 | C22: Incidencia | D22: Hola, buenos días ¡Hola! Soy Corporín, tu asistente virtual de AVIS Corporate en Canarias. ¿En qué puedo ayudarte hoy? Llevo desde ayer intentando hacer una reserva y no me deja "Entiendo que llevas desde ayer intentando hacer una reserva y no te deja. Para poder ayudarte y compensar el inconveniente, por favor, cancela la reserva actual (si existe) e intenta generar una nueva. Además, facilítame tu DNI para poder gestionar tu incidencia correctamente y tramitar una posible compensación. ¿Podrías indicarme tu DNI, por favor?" 42258758N "Tu incidencia ha sido registrada y enviada a nuestro departamento de Atención al Cliente. En los próximos días se tramitará la devolución o compensación correspondiente. ¿Hay algo más en lo que pueda ayudarte?" Si , necesito hacer la reserva para el viernes "Para hacer la reserva para el viernes, debes usar la app de AVIS Corporate Canarias. En la app podrás seleccionar la categoría de vehículo que prefieras (económico, compacto, SUV, monovolumen, etc.), ya que no se puede elegir un modelo específico. La app te mostrará los vehículos disponibles en tiempo real para las fechas que elijas. Recuerda que para formalizar la reserva es obligatorio presentar una tarjeta de crédito a tu nombre para bloquear la fianza. También debes tener al menos 21 años y un año mínimo de antigüedad en tu permiso de conducir. ¿Necesitas que te ayude con algo más?" Ponga el día que ponga y la fecha que ponga Tu solicitud ha sido enviada. Un agente de soporte te atenderá lo antes posible. Gracias por tu paciencia. Gracias ¡Gracias a ti por contactar con AVIS Corporate Canarias! Si necesitas cualquier otra cosa en el futuro, aquí estaré para ayudarte. ¡Que tengas un gran día! Igualmente ! ¡Gracias a ti! Si necesitas cualquier otra cosa en el futuro, aquí estaré para ayudarte. ¡Que tengas un gran día! | E22: NOK | F22: NOK | G22: Mejorable | H22: No es capaz de detectar el problema que tiene el cliente
A23: 34609152656 | B23: 28-09-2025 11:35 | C23: Incidencia | D23: Una pregunta Y el coche no cierra "¡Hola! Soy Corporín, tu asistente virtual de AVIS Corporate en Canarias. He visto que comentas que el coche no cierra. Para poder ayudarte mejor, ¿puedes confirmarme si el problema es que el botón de abrir/cerrar en la app se queda cargando y no responde, o se trata de otra situación diferente? Así podré darte la solución más adecuada. ¡Gracias!" El boton queda cargando Pero es en un parking Que no hay cobertura Tiene que ver algo von eso? "¡Gracias por la información! Por lo que comentas, el botón de abrir/cerrar en la app se queda cargando y además estás en un parking sin cobertura. Esto puede estar relacionado, ya que la app necesita conexión para funcionar correctamente. Por favor, prueba a reiniciar sesión en la app. Si después de hacer esto el problema continúa, avísame para escalar la incidencia y ayudarte a resolverlo cuanto antes. Recuerda que actualmente estamos fuera de nuestro horario laboral (lunes a viernes, de 08:00 a 20:00 en Canarias), pero dejaré tu caso preparado para que lo gestionemos en cuanto volvamos a estar operativos. ¿Puedes probarlo y confirmarme si se soluciona?" Vale y en el caso que no tenga cobertura No me va a abrir el coche? Si no tienes cobertura en el parking, la app no podrá comunicarse para abrir el coche, por lo que no podrás abrirlo con la app en esa situación. Te recomiendo asegurarte de tener conexión de datos para usar la llave digital. ¿Necesitas que te ayude con algo más? Y en el caso de que no pueda abrir el coche me lo podeis abrir a remoto? Si no puedes abrir el vehículo con la app, primero revisa que tu móvil tenga conexión de datos y Bluetooth/GPS activado. Si sigue sin funcionar, debes llamar al Centro de Atención 24 h al 928 092 337, donde te guiarán para reactivar la llave digital o te proporcionarán asistencia presencial. ¿Necesitas que te ayude con algo más? | E23: NOK | F23: NOK | G23: Mal | H23: Sin cobertura, con bluetooth, debe funcionar
A24: 34662917448 | B24: 28-09-2025 18:25 | C24: Consulta | D24: Hola No sé si el coche tiene gasolina o diésel Los vehículos disponibles en AVIS Corporate Canarias pueden variar en modelo y características, y se asigna uno de la categoría reservada en el punto de entrega. No se especifica en la información si el coche tiene gasolina o diésel. Para detalles específicos sobre el tipo de combustible, te recomiendo consultarlo en la app al momento de la reserva o en la entrega del vehículo. ¿Necesitas que te ayude con algo más? | E24: OK | F24: OK | G24: Mejorable | H24: Son todos gasolina actualmente
A25: 34659845211 | B25: 27-09-2025 19:18 | D25: Buenas tardes No abre el parking de gran canaria no reconoce la matrícula ¡Hola! Soy Corporín, tu asistente virtual de AVIS Corporate en Canarias. ¿En qué puedo ayudarte hoy? "He revisado el historial y la configuración de incidencias. El problema que describes (""No abre el parking de Gran Canaria, no reconoce la matrícula"") no encaja exactamente con las subincidencias estándar de ""No puede abrir coche"", ya que está relacionado con el acceso al parking por reconocimiento de matrícula, no con la apertura del vehículo en sí. Para poder ayudarte correctamente, ¿puedes confirmar si el problema es que: - No puedes acceder al parking porque la barrera no reconoce la matrícula de tu coche de alquiler, - O si el problema es que no puedes abrir el coche una vez dentro del parking? Por favor, indícame cuál de estas situaciones describe mejor tu problema para poder gestionarlo de la forma más adecuada." No abre el parking car rental "La barrera no reconoce la Matrícula de mi coche de alquiler" "Gracias por la información. Para poder gestionar tu incidencia de acceso al parking de alquiler (barrera que no reconoce la matrícula), ¿podrías facilitarme tu DNI? Así podremos registrar el caso y asegurarnos de que nuestro Call Center te contacte en cuanto estemos en horario laboral. ¿Me lo puedes indicar, por favor?" 43836861B "Gracias por facilitar tu DNI. Hemos registrado tu incidencia: la barrera del parking de alquiler en Gran Canaria no reconoce la matrícula de tu coche y no puedes acceder. Actualmente estamos fuera de nuestro horario laboral (lunes a viernes, de 08:00 a 20:00 en Canarias). Se ha enviado tu caso a nuestro Call Center y te llamarán cuando estemos en horario laboral para ayudarte a resolverlo lo antes posible. ¿Necesitas ayuda con algo más?" No No me has ayudado Puedo modificar el horario de entrega del vehículo? Para antes "¡Muchas gracias por tu respuesta! Hemos registrado tu incidencia correctamente y nuestro Call Center te contactará en cuanto estemos en horario laboral para ayudarte con el acceso al parking. Que tengas buena tarde. Si necesitas cualquier otra cosa en el futuro, aquí estaré para ayudarte." No es posible adelantar la recogida del vehículo desde la app. Para cambiar el horario de entrega a uno anterior, te recomendamos cancelar la reserva actual sin coste (siempre que sea antes de la fecha de inicio) y hacer una nueva reserva con el horario deseado. ¿Necesitas que te ayude con algo más? Tu solicitud ha sido enviada. Un agente de soporte te atenderá lo antes posible. Gracias por tu paciencia. | E25: NOK | F25: NOK | G25: Mejorable | H25: Segunda parte OK, la primera NOK
A26: 34605074230 | B26: 27-09-2025 18:45 | C26: Incidencia | D26: No me deja iniciar el vije No me deja iniciar el viaje "¡Hola! Soy Corporín, tu asistente virtual de AVIS Corporate en Canarias. Veo que tienes problemas para iniciar tu viaje. Para poder ayudarte mejor, ¿podrías decirme cuál de estas situaciones describe mejor tu problema? 1. No puedes abrir el coche (ni con llave física ni digital) 2. No aparece la llave digital en tu aplicación 3. El botón de abrir/cerrar se queda cargando y no responde 4. El coche muestra una pantalla verde 5. El coche no detecta la llave aunque estás dentro Por favor, dime cuál se ajusta más a lo que te ocurre. Así podré darte la mejor solución posible." "¡Hola! Soy Corporín, tu asistente virtual de AVIS Corporate en Canarias. He visto que indicas que no puedes iniciar el viaje. Para poder ayudarte mejor, ¿puedes decirme cuál de estas situaciones describe mejor tu problema? 1. El vehículo no está disponible o no lo ves en la app. 2. No aparece la llave digital en la aplicación. 3. El botón de abrir/cerrar se queda cargando y no responde. 4. Ves una pantalla verde en la app o sistema del coche. Por favor, dime cuál de estas opciones se ajusta más a lo que te ocurre, así podré darte la mejor solución. Recuerda que actualmente estamos fuera de nuestro horario laboral (lunes a viernes, de 08:00 a 20:00 en Canarias), pero dejaré tu incidencia registrada para que te contacten lo antes posible." 1 "¡Gracias por tu respuesta! Para poder gestionar tu incidencia correctamente y ayudarte a abrir el coche, por favor, facilítame tu DNI. En cuanto lo reciba, registraré tu incidencia y nuestro Call Center te llamará cuando estemos en horario laboral (08:00 a 20:00h de lunes a viernes, UTC+1). ¿Puedes indicarme tu DNI, por favor?" Y4191183E "¡Gracias por facilitar tu DNI! He registrado tu incidencia: nuestro Call Center te llamará cuando estemos en horario laboral (de lunes a viernes, de 08:00 a 20:00 en Canarias) para ayudarte a resolver el problema con la apertura del coche. ¿Necesitas ayuda con algo más?" No puedo cancelar una reserva porque no me deja abrir el contrato "¡Gracias por la información! He registrado tu incidencia: no puedes cancelar la reserva porque no te permite abrir el contrato. Actualmente estamos fuera de nuestro horario laboral (lunes a viernes, de 08:00 a 20:00 en Canarias), pero nuestro equipo de Atención al Cliente te contactará en cuanto estemos disponibles para ayudarte a resolverlo. ¿Necesitas ayuda con algo más?"
A27: 34616397458 | B27: 27-09-2025 17:19 | C27: Incidencia | D27: Hola ¡Hola! Soy Corporín, tu asistente virtual de AVIS Corporate en Canarias. ¿En qué puedo ayudarte hoy? No está nuestro coche "Entiendo que no encuentras el coche en el lugar acordado. Por favor, revisa en el mapa de tu aplicación la ubicación exacta del vehículo, ya que ahí debería aparecerte el punto donde está estacionado. ¿Puedes confirmarme si lo localizas en el mapa o sigues teniendo problemas?" No está "He revisado el historial y la incidencia corresponde a ""El coche no aparece"", ya que el cliente ha confirmado que no encuentra el vehículo ni en el lugar acordado ni en el mapa de la aplicación. Según el procedimiento, el siguiente paso es solicitar el DNI del cliente para poder gestionar la incidencia correctamente. Además, como estamos fuera de horario laboral, una vez recibido el DNI, se enviará la incidencia al Call Center y se informará al cliente de que será contactado cuando estemos en horario laboral. Mensaje para el cliente: Por favor, facilítenos su DNI para poder gestionar su incidencia correctamente. Cuando lo recibamos, enviaremos la incidencia a nuestro Call Center y le llamarán cuando estemos en horario laboral (08:00 a 20:00h de lunes a viernes, UTC+1)." 78592898N "Gracias por facilitarnos tu DNI. Hemos enviado tu incidencia a nuestro Call Center. Te llamarán cuando estemos en horario laboral (de lunes a viernes, de 08:00 a 20:00, hora Canarias) para ayudarte a resolver el problema. ¿Hay algo más en lo que pueda ayudarte?" | E27: NOK | F27: NOK | G27: Mal | H27: Le está dictando su propio procedimiento
